Workbook

Sheet XDR-USD
A1: Least Squares autoregression
A3: n | B3: 0 | C3: 1 | D3: 2 | E3: 3 | F3: 4 | G3: 5 | H3: 6 | I3: 7 | J3: 8 | K3: 9 | L3: 10 | M3: 11 | N3: 12 | O3: 13 | P3: 14 | Q3: 15 | R3: 16 | S3: 17 | T3: 18 | U3: 19 | V3: 20 | W3: 21 | X3: 22 | Y3: 23 | Z3: 24 | AA3: 25 | AB3: 26 | AC3: 27 | AD3: 28 | AE3: 29 | AF3: 30 | AG3: 31 | AH3: 32 | AI3: 33 | AJ3: 34 | AK3: 35 | AL3: 36 | AM3: 37 | AN3: 38 | AO3: 39 | AP3: 40 | AQ3: 41 | AR3: 42 | AS3: 43 | AT3: 44 | AU3: 45 | AV3: 46 | AW3: 47 | AX3: 48 | AY3: 49 | AZ3: 50 | BA3: 51 | BB3: 52 | BC3: 53 | BD3: 54 | BE3: 55 | BF3: 56 | BG3: 57 | BH3: 58 | BI3: 59 | BJ3: 60 | BK3: 61 | BL3: 62 | BM3: 63 | BN3: 64 | BO3: 65 | BP3: 66 | BQ3: 67 | BR3: 68 | BS3: 69 | BT3: 70 | BU3: 71 | BV3: 72 | BW3: 73 | BX3: 74 | BY3: 75 | BZ3: 76 | CA3: 77 | CB3: 78 | CC3: 79 | CD3: 80 | CE3: 81 | CF3: 82 | CG3: 83 | CH3: 84 | CI3: 85 | CJ3: 86 | CK3: 87 | CL3: 88 | CM3: 89 | CN3: 90 | CO3: 91 | CP3: 92 | CQ3: 93 | CR3: 94 | CS3: 95 | CT3: 96 | CU3: 97 | CV3: 98 | CW3: 99 | CX3: 100 | CY3: 101 | CZ3: 102 | DA3: 103 | DB3: 104 | DC3: 105 | DD3: 106 | DE3: 107 | DF3: 108 | DG3: 109 | DH3: 110 | DI3: 111 | DJ3: 112 | DK3: 113 | DL3: 114 | DM3: 115 | DN3: 116 | DO3: 117 | DP3: 118 | DQ3: 119 | DR3: 120 | DS3: 121 | DT3: 122 | DU3: 123 | DV3: 124 | DW3: 125 | DX3: 126 | DY3: 127 | DZ3: 128 | EA3: 129 | EB3: 130 | EC3: 131 | ED3: 132 | EE3: 133 | EF3: 134 | EG3: 135 | EH3: 136 | EI3: 137 | EJ3: 138 | EK3: 139 | EL3: 140 | EM3: 141 | EN3: 142 | EO3: 143 | EP3: 144 | EQ3: 145 | ER3: 146 | ES3: 147 | ET3: 148 | EU3: 149 | EV3: 150 | EW3: 151 | EX3: 152 | EY3: 153 | EZ3: 154 | FA3: 155 | FB3: 156 | FC3: 157 | FD3: 158 | FE3: 159 | FF3: 160 | FG3: 161 | FH3: 162 | FI3: 163 | FJ3: 164 | FK3: 165 | FL3: 166 | FM3: 167 | FN3: 168 | FO3: 169 | FP3: 170 | FQ3: 171 | FR3: 172 | FS3: 173 | FT3: 174 | FU3: 175 | FV3: 176 | FW3: 177 | FX3: 178 | FY3: 179 | FZ3: 180 | GA3: 181 | GB3: 182 | GC3: 183 | GD3: 184 | GE3: 185 | GF3: 186 | GG3: 187 | GH3: 188 | GI3: 189 | GJ3: 190 | GK3: 191 | GL3: 192 | GM3: 193 | GN3: 194 | GO3: 195 | GP3: 196 | GQ3: 197 | GR3: 198 | GS3: 199 | GT3: 200 | GU3: 201 | GV3: 202 | GW3: 203 | GX3: 204 | GY3: 205 | GZ3: 206 | HA3: 207 | HB3: 208 | HC3: 209 | HD3: 210 | HE3: 211 | HF3: 212 | HG3: 213 | HH3: 214 | HI3: 215 | HJ3: 216 | HK3: 217 | HL3: 218 | HM3: 219 | HN3: 220 | HO3: 221 | HP3: 222 | HQ3: 223 | HR3: 224 | HS3: 225 | HT3: 226 | HU3: 227 | HV3: 228 | HW3: 229 | HX3: 230 | HY3: 231 | HZ3: 232 | IA3: 233 | IB3: 234 | IC3: 235 | ID3: 236 | IE3: 237 | IF3: 238 | IG3: 239 | IH3: 240 | II3: 241 | IJ3: 242 | IK3: 243 | IL3: 244 | IM3: 245 | IN3: 246 | IO3: 247 | IP3: 248
A4: x | B4: 0.748168 | C4: 0.746229 | D4: 0.743531 | E4: 0.740922 | F4: 0.744055 | G4: 0.74295 | H4: 0.744509 | I4: 0.73924 | J4: 0.740056 | K4: 0.737067 | L4: 0.737615 | M4: 0.738881 | N4: 0.736349 | O4: 0.73566 | P4: 0.735201 | Q4: 0.736019 | R4: 0.737741 | S4: 0.738338 | T4: 0.735928 | U4: 0.733682 | V4: 0.732694 | W4: 0.735814 | X4: 0.735191 | Y4: 0.737321 | Z4: 0.737407 | AA4: 0.736437 | AB4: 0.738543 | AC4: 0.738339 | AD4: 0.738476 | AE4: 0.740788 | AF4: 0.738321 | AG4: 0.738073 | AH4: 0.740826 | AI4: 0.741312 | AJ4: 0.740009 | AK4: 0.738019 | AL4: 0.739242 | AM4: 0.738611 | AN4: 0.741586 | AO4: 0.742416 | AP4: 0.742697 | AQ4: 0.741199 | AR4: 0.741765 | AS4: 0.742524 | AT4: 0.742643 | AU4: 0.742118 | AV4: 0.739908 | AW4: 0.741417 | AX4: 0.740962 | AY4: 0.737426 | AZ4: 0.737019 | BA4: 0.736545 | BB4: 0.734522 | BC4: 0.734349 | BD4: 0.734089 | BE4: 0.733615 | BF4: 0.731474 | BG4: 0.732123 | BH4: 0.734287 | BI4: 0.73534 | BJ4: 0.737002 | BK4: 0.737026 | BL4: 0.737096 | BM4: 0.736625 | BN4: 0.736951 | BO4: 0.737741 | BP4: 0.739368 | BQ4: 0.738213 | BR4: 0.737479 | BS4: 0.736055 | BT4: 0.736167 | BU4: 0.735711 | BV4: 0.734766 | BW4: 0.732683 | BX4: 0.732379 | BY4: 0.733628 | BZ4: 0.730816 | CA4: 0.730498 | CB4: 0.730764 | CC4: 0.730413 | CD4: 0.729382 | CE4: 0.730224 | CF4: 0.730248 | CG4: 0.730316 | CH4: 0.730504 | CI4: 0.729562 | CJ4: 0.729715 | CK4: 0.731662 | CL4: 0.732056 | CM4: 0.732358 | CN4: 0.732325 | CO4: 0.729733 | CP4: 0.728194 | CQ4: 0.726032 | CR4: 0.72421 | CS4: 0.724322 | CT4: 0.722952 | CU4: 0.722859 | CV4: 0.724108 | CW4: 0.723333 | CX4: 0.72279 | CY4: 0.724326 | CZ4: 0.722376 | DA4: 0.722137 | DB4: 0.722906 | DC4: 0.721647 | DD4: 0.720682 | DE4: 0.721697 | DF4: 0.721325 | DG4: 0.723519 | DH4: 0.722916 | DI4: 0.722954 | DJ4: 0.723104 | DK4: 0.723486 | DL4: 0.724175 | DM4: 0.723335 | DN4: 0.725467 | DO4: 0.725308 | DP4: 0.725165 | DQ4: 0.724885 | DR4: 0.724998 | DS4: 0.7229 | DT4: 0.720685 | DU4: 0.719101 | DV4: 0.718707 | DW4: 0.720059 | DX4: 0.721747 | DY4: 0.720427 | DZ4: 0.720031 | EA4: 0.720812 | EB4: 0.720627 | EC4: 0.71913 | ED4: 0.719778 | EE4: 0.71918 | EF4: 0.717275 | EG4: 0.715114 | EH4: 0.715701 | EI4: 0.716878 | EJ4: 0.713352 | EK4: 0.712579 | EL4: 0.712941 | EM4: 0.713242 | EN4: 0.711216 | EO4: 0.71147 | EP4: 0.710354 | EQ4: 0.708254 | ER4: 0.70792 | ES4: 0.708005 | ET4: 0.707254 | EU4: 0.709495 | EV4: 0.70877 | EW4: 0.710034 | EX4: 0.71 | EY4: 0.709136 | EZ4: 0.708845 | FA4: 0.71055 | FB4: 0.711843 | FC4: 0.711461 | FD4: 0.709706 | FE4: 0.709489 | FF4: 0.709876 | FG4: 0.709413 | FH4: 0.709047 | FI4: 0.708581 | FJ4: 0.705414 | FK4: 0.702778 | FL4: 0.7051 | FM4: 0.707519 | FN4: 0.705531 | FO4: 0.705231 | FP4: 0.703781 | FQ4: 0.702101 | FR4: 0.69897 | FS4: 0.701262 | FT4: 0.703162 | FU4: 0.702272 | FV4: 0.704516 | FW4: 0.702343 | FX4: 0.702671 | FY4: 0.7026 | FZ4: 0.701882 | GA4: 0.704774 | GB4: 0.702884 | GC4: 0.705428 | GD4: 0.707239 | GE4: 0.708837 | GF4: 0.708352 | GG4: 0.707566 | GH4: 0.709577 | GI4: 0.70965 | GJ4: 0.708659 | GK4: 0.709771 | GL4: 0.711305 | GM4: 0.708152 | GN4: 0.707444 | GO4: 0.706904 | GP4: 0.706831 | GQ4: 0.70703 | GR4: 0.708893 | GS4: 0.70955 | GT4: 0.708 | GU4: 0.708683 | GV4: 0.710431 | GW4: 0.70996 | GX4: 0.709671 | GY4: 0.708701 | GZ4: 0.713278 | HA4: 0.712493 | HB4: 0.711903 | HC4: 0.711691 | HD4: 0.712151 | HE4: 0.712581 | HF4: 0.713708 | HG4: 0.714157 | HH4: 0.713343 | HI4: 0.712478 | HJ4: 0.712515 | HK4: 0.712471 | HL4: 0.711022 | HM4: 0.707746 | HN4: 0.709595 | HO4: 0.708747 | HP4: 0.708751 | HQ4: 0.709918 | HR4: 0.708794 | HS4: 0.704217 | HT4: 0.70549 | HU4: 0.705975 | HV4: 0.706505 | HW4: 0.70491 | HX4: 0.70609 | HY4: 0.70612 | HZ4: 0.70724 | IA4: 0.708142 | IB4: 0.708986 | IC4: 0.70818 | ID4: 0.708681 | IE4: 0.709315 | IF4: 0.706844 | IG4: 0.707184 | IH4: 0.707695 | II4: 0.707246 | IJ4: 0.706632 | IK4: 0.706255 | IL4: 0.706353 | IM4: 0.705664 | IN4: 0.705257 | IO4: 0.703879 | IP4: 0.702181
A5: y, N=50, P=8 | B5: 0 | C5: 0 | D5: 0 | E5: 0 | F5: 0 | G5: 0 | H5: 0 | I5: 0 | J5: 0 | K5: 0 | L5: 0 | M5: 0 | N5: 0 | O5: 0 | P5: 0 | Q5: 0 | R5: 0 | S5: 0 | T5: 0 | U5: 0 | V5: 0 | W5: 0 | X5: 0 | Y5: 0 | Z5: 0 | AA5: 0 | AB5: 0 | AC5: 0 | AD5: 0 | AE5: 0 | AF5: 0 | AG5: 0 | AH5: 0 | AI5: 0 | AJ5: 0 | AK5: 0 | AL5: 0 | AM5: 0 | AN5: 0 | AO5: 0 | AP5: 0 | AQ5: 0 | AR5: 0 | AS5: 0 | AT5: 0 | AU5: 0 | AV5: 0 | AW5: 0 | AX5: 0 | AY5: 0 | AZ5: 0 | BA5: 0 | BB5: 0 | BC5: 0 | BD5: 0 | BE5: 0 | BF5: 0 | BG5: 0.731403 | BH5: 0.731635 | BI5: 0.733746 | BJ5: 0.734961 | BK5: 0.736353 | BL5: 0.736429 | BM5: 0.73726 | BN5: 0.737019 | BO5: 0.737564 | BP5: 0.738134 | BQ5: 0.73937 | BR5: 0.737995 | BS5: 0.737666 | BT5: 0.736347 | BU5: 0.736428 | BV5: 0.735717 | BW5: 0.734404 | BX5: 0.732296 | BY5: 0.732399 | BZ5: 0.733092 | CA5: 0.730099 | CB5: 0.730619 | CC5: 0.73028 | CD5: 0.729598 | CE5: 0.729326 | CF5: 0.730158 | CG5: 0.729687 | CH5: 0.730011 | CI5: 0.730504 | CJ5: 0.7292 | CK5: 0.729894 | CL5: 0.731628 | CM5: 0.731603 | CN5: 0.732451 | CO5: 0.732201 | CP5: 0.729186 | CQ5: 0.727759 | CR5: 0.724652 | CS5: 0.723597 | CT5: 0.723808 | CU5: 0.722265 | CV5: 0.723345 | CW5: 0.724073 | CX5: 0.72299 | CY5: 0.723044 | CZ5: 0.724102 | DA5: 0.72174 | DB5: 0.722467 | DC5: 0.722141 | DD5: 0.721307 | DE5: 0.721028 | DF5: 0.72071 | DG5: 0.72137 | DH5: 0.723899 | DI5: 0.722325 | DJ5: 0.723016 | DK5: 0.7231 | DL5: 0.722962 | DM5: 0.724227 | DN5: 0.722762 | DO5: 0.725358 | DP5: 0.724886 | DQ5: 0.725462 | DR5: 0.724511 | DS5: 0.724157 | DT5: 0.722415 | DU5: 0.720051 | DV5: 0.718058 | DW5: 0.718069 | DX5: 0.720923 | DY5: 0.722311 | DZ5: 0.720586 | EA5: 0.719927 | EB5: 0.720263 | EC5: 0.720439 | ED5: 0.718944 | EE5: 0.71906 | EF5: 0.71864 | EG5: 0.717137 | EH5: 0.714586 | EI5: 0.715389 | EJ5: 0.716197 | EK5: 0.713184 | EL5: 0.713319 | EM5: 0.712481 | EN5: 0.712306 | EO5: 0.71114 | EP5: 0.711626 | EQ5: 0.709743 | ER5: 0.707967 | ES5: 0.708063 | ET5: 0.707287 | EU5: 0.707071 | EV5: 0.709486 | EW5: 0.708473 | EX5: 0.709948 | EY5: 0.709763 | EZ5: 0.708621 | FA5: 0.70889 | FB5: 0.710402 | FC5: 0.711399 | FD5: 0.711202 | FE5: 0.709704 | FF5: 0.709375 | FG5: 0.709367 | FH5: 0.708991 | FI5: 0.709107 | FJ5: 0.708205 | FK5: 0.704263 | FL5: 0.703039 | FM5: 0.70618 | FN5: 0.706266 | FO5: 0.704342 | FP5: 0.705404 | FQ5: 0.702345 | FR5: 0.701107 | FS5: 0.700386 | FT5: 0.70248 | FU5: 0.702226 | FV5: 0.701361 | FW5: 0.704053 | FX5: 0.701088 | FY5: 0.701498 | FZ5: 0.702797 | GA5: 0.70275 | GB5: 0.703611 | GC5: 0.703732 | GD5: 0.704795 | GE5: 0.706782 | GF5: 0.709004 | GG5: 0.707601 | GH5: 0.709082 | GI5: 0.708944 | GJ5: 0.710448 | GK5: 0.709499 | GL5: 0.710286 | GM5: 0.710847 | GN5: 0.707741 | GO5: 0.708502 | GP5: 0.706901 | GQ5: 0.706904 | GR5: 0.707545 | GS5: 0.709651 | GT5: 0.707975 | GU5: 0.707651 | GV5: 0.708658 | GW5: 0.710189 | GX5: 0.70982 | GY5: 0.710332 | GZ5: 0.709268 | HA5: 0.712593 | HB5: 0.711865 | HC5: 0.712945 | HD5: 0.711539 | HE5: 0.712483 | HF5: 0.711935 | HG5: 0.715535 | HH5: 0.713794 | HI5: 0.713335 | HJ5: 0.712737 | HK5: 0.712896 | HL5: 0.712704 | HM5: 0.711489 | HN5: 0.708774 | HO5: 0.709765 | HP5: 0.708818 | HQ5: 0.709206 | HR5: 0.709741 | HS5: 0.708666 | HT5: 0.704573 | HU5: 0.706487 | HV5: 0.705428 | HW5: 0.705712 | HX5: 0.705461 | HY5: 0.70591 | HZ5: 0.705699 | IA5: 0.70703 | IB5: 0.708315 | IC5: 0.708431 | ID5: 0.708186 | IE5: 0.70904 | IF5: 0.709266 | IG5: 0.706895 | IH5: 0.707996 | II5: 0.707607 | IJ5: 0.706663 | IK5: 0.707033 | IL5: 0.706149 | IM5: 0.70616 | IN5: 0.705771 | IO5: 0.705316 | IP5: 0.703899

Sheet SDR-USD
A1: Least Squares autoregression
